Traceback (most recent call last):
  File "C:\Users\omtoi\OneDrive\Documents\SecureHome-main\SecureHome-main\main.py", line 151, in <module>
    face_locations, face_names = fr.detect_known_faces(frame)
                                 ^^^^^^^^^^^^^^^^^^^^^^^^^^^^
  File "C:\Users\omtoi\OneDrive\Documents\SecureHome-main\SecureHome-main\dependencies\Facerec.py", line 52, in detect_known_faces
    face_encodings = face_recognition.face_encodings(rgb_small_frame, face_locations)
                     ^^^^^^^^^^^^^^^^^^^^^^^^^^^^^^^^^^^^^^^^^^^^^^^^^^^^^^^^^^^^^^^^
  File "C:\Users\omtoi\AppData\Local\Programs\Python\Python312\Lib\site-packages\face_recognition\api.py", line 213, in face_encodings
    return [np.array(face_encoder.compute_face_descriptor(face_image, raw_landmark_set, num_jitters)) for raw_landmark_set in raw_landmarks]
                     ^^^^^^^^^^^^^^^^^^^^^^^^^^^^^^^^^^^^^^^^^^^^^^^^^^^^^^^^^^^^^^^^^^^^^^^^^^^^^^^
KeyboardInterrupt
NoneType: None
Traceback (most recent call last):
  File "C:\Users\omtoi\OneDrive\Documents\SecureHome-main\SecureHome-main\main.py", line 151, in <module>
    face_locations, face_names = fr.detect_known_faces(frame)
                                 ^^^^^^^^^^^^^^^^^^^^^^^^^^^^
  File "C:\Users\omtoi\OneDrive\Documents\SecureHome-main\SecureHome-main\dependencies\Facerec.py", line 51, in detect_known_faces
    face_locations = face_recognition.face_locations(rgb_small_frame)
                     ^^^^^^^^^^^^^^^^^^^^^^^^^^^^^^^^^^^^^^^^^^^^^^^^
  File "C:\Users\omtoi\AppData\Local\Programs\Python\Python312\Lib\site-packages\face_recognition\api.py", line 120, in face_locations
    return [_trim_css_to_bounds(_rect_to_css(face), img.shape) for face in _raw_face_locations(img, number_of_times_to_upsample, model)]
                                                                           ^^^^^^^^^^^^^^^^^^^^^^^^^^^^^^^^^^^^^^^^^^^^^^^^^^^^^^^^^^^^
  File "C:\Users\omtoi\AppData\Local\Programs\Python\Python312\Lib\site-packages\face_recognition\api.py", line 104, in _raw_face_locations
    return face_detector(img, number_of_times_to_upsample)
           ^^^^^^^^^^^^^^^^^^^^^^^^^^^^^^^^^^^^^^^^^^^^^^^
KeyboardInterrupt
NoneType: None
Traceback (most recent call last):
  File "C:\Users\omtoi\OneDrive\Documents\SecureHome-main\SecureHome-main\main.py", line 151, in <module>
    face_locations, face_names = fr.detect_known_faces(frame)
                                 ^^^^^^^^^^^^^^^^^^^^^^^^^^^^
  File "C:\Users\omtoi\OneDrive\Documents\SecureHome-main\SecureHome-main\dependencies\Facerec.py", line 51, in detect_known_faces
    face_locations = face_recognition.face_locations(rgb_small_frame)
                     ^^^^^^^^^^^^^^^^^^^^^^^^^^^^^^^^^^^^^^^^^^^^^^^^
  File "C:\Users\omtoi\AppData\Local\Programs\Python\Python312\Lib\site-packages\face_recognition\api.py", line 120, in face_locations
    return [_trim_css_to_bounds(_rect_to_css(face), img.shape) for face in _raw_face_locations(img, number_of_times_to_upsample, model)]
                                                                           ^^^^^^^^^^^^^^^^^^^^^^^^^^^^^^^^^^^^^^^^^^^^^^^^^^^^^^^^^^^^
  File "C:\Users\omtoi\AppData\Local\Programs\Python\Python312\Lib\site-packages\face_recognition\api.py", line 104, in _raw_face_locations
    return face_detector(img, number_of_times_to_upsample)
           ^^^^^^^^^^^^^^^^^^^^^^^^^^^^^^^^^^^^^^^^^^^^^^^
KeyboardInterrupt
NoneType: None
Traceback (most recent call last):
  File "C:\Users\omtoi\OneDrive\Documents\SecureHome-main\SecureHome-main\main.py", line 128, in <module>
    gray = cv2.cvtColor(diff, cv2.COLOR_BGR2GRAY)
           ^^^^^^^^^^^^^^^^^^^^^^^^^^^^^^^^^^^^^^
cv2.error: OpenCV(4.7.0) D:\a\opencv-python\opencv-python\opencv\modules\imgproc\src\color.cpp:182: error: (-215:Assertion failed) !_src.empty() in function 'cv::cvtColor'

NoneType: None
Traceback (most recent call last):
  File "C:\Users\omtoi\OneDrive\Documents\SecureHome-main\SecureHome-main\main.py", line 128, in <module>
    gray = cv2.cvtColor(diff, cv2.COLOR_BGR2GRAY)
           ^^^^^^^^^^^^^^^^^^^^^^^^^^^^^^^^^^^^^^
cv2.error: OpenCV(4.7.0) D:\a\opencv-python\opencv-python\opencv\modules\imgproc\src\color.cpp:182: error: (-215:Assertion failed) !_src.empty() in function 'cv::cvtColor'

NoneType: None
Traceback (most recent call last):
  File "C:\Users\omtoi\OneDrive\Documents\SecureHome-main\SecureHome-main\main.py", line 151, in <module>
    face_locations, face_names = fr.detect_known_faces(frame)
                                 ^^^^^^^^^^^^^^^^^^^^^^^^^^^^
  File "C:\Users\omtoi\OneDrive\Documents\SecureHome-main\SecureHome-main\dependencies\Facerec.py", line 52, in detect_known_faces
    face_encodings = face_recognition.face_encodings(rgb_small_frame, face_locations)
                     ^^^^^^^^^^^^^^^^^^^^^^^^^^^^^^^^^^^^^^^^^^^^^^^^^^^^^^^^^^^^^^^^
  File "C:\Users\omtoi\AppData\Local\Programs\Python\Python312\Lib\site-packages\face_recognition\api.py", line 213, in face_encodings
    return [np.array(face_encoder.compute_face_descriptor(face_image, raw_landmark_set, num_jitters)) for raw_landmark_set in raw_landmarks]
                     ^^^^^^^^^^^^^^^^^^^^^^^^^^^^^^^^^^^^^^^^^^^^^^^^^^^^^^^^^^^^^^^^^^^^^^^^^^^^^^^
KeyboardInterrupt
NoneType: None
Traceback (most recent call last):
  File "C:\Users\omtoi\OneDrive\Documents\SecureHome-main\SecureHome-main\main.py", line 151, in <module>
    face_locations, face_names = fr.detect_known_faces(frame)
                                 ^^^^^^^^^^^^^^^^^^^^^^^^^^^^
  File "C:\Users\omtoi\OneDrive\Documents\SecureHome-main\SecureHome-main\dependencies\Facerec.py", line 52, in detect_known_faces
    face_encodings = face_recognition.face_encodings(rgb_small_frame, face_locations)
                     ^^^^^^^^^^^^^^^^^^^^^^^^^^^^^^^^^^^^^^^^^^^^^^^^^^^^^^^^^^^^^^^^
  File "C:\Users\omtoi\AppData\Local\Programs\Python\Python312\Lib\site-packages\face_recognition\api.py", line 213, in face_encodings
    return [np.array(face_encoder.compute_face_descriptor(face_image, raw_landmark_set, num_jitters)) for raw_landmark_set in raw_landmarks]
                     ^^^^^^^^^^^^^^^^^^^^^^^^^^^^^^^^^^^^^^^^^^^^^^^^^^^^^^^^^^^^^^^^^^^^^^^^^^^^^^^
KeyboardInterrupt
NoneType: None
Traceback (most recent call last):
  File "C:\Users\omtoi\OneDrive\Documents\SecureHome-main\SecureHome-main\main.py", line 128, in <module>
    gray = cv2.cvtColor(diff, cv2.COLOR_BGR2GRAY)
           ^^^^^^^^^^^^^^^^^^^^^^^^^^^^^^^^^^^^^^
cv2.error: OpenCV(4.7.0) D:\a\opencv-python\opencv-python\opencv\modules\imgproc\src\color.cpp:182: error: (-215:Assertion failed) !_src.empty() in function 'cv::cvtColor'

NoneType: None
Traceback (most recent call last):
  File "C:\Users\omtoi\OneDrive\Documents\SecureHome-main\SecureHome-main\main.py", line 151, in <module>
    face_locations, face_names = fr.detect_known_faces(frame)
                                 ^^^^^^^^^^^^^^^^^^^^^^^^^^^^
  File "C:\Users\omtoi\OneDrive\Documents\SecureHome-main\SecureHome-main\dependencies\Facerec.py", line 51, in detect_known_faces
    face_locations = face_recognition.face_locations(rgb_small_frame)
                     ^^^^^^^^^^^^^^^^^^^^^^^^^^^^^^^^^^^^^^^^^^^^^^^^
  File "C:\Users\omtoi\AppData\Local\Programs\Python\Python312\Lib\site-packages\face_recognition\api.py", line 120, in face_locations
    return [_trim_css_to_bounds(_rect_to_css(face), img.shape) for face in _raw_face_locations(img, number_of_times_to_upsample, model)]
                                                                           ^^^^^^^^^^^^^^^^^^^^^^^^^^^^^^^^^^^^^^^^^^^^^^^^^^^^^^^^^^^^
  File "C:\Users\omtoi\AppData\Local\Programs\Python\Python312\Lib\site-packages\face_recognition\api.py", line 104, in _raw_face_locations
    return face_detector(img, number_of_times_to_upsample)
           ^^^^^^^^^^^^^^^^^^^^^^^^^^^^^^^^^^^^^^^^^^^^^^^
KeyboardInterrupt
NoneType: None
Traceback (most recent call last):
  File "C:\Users\omtoi\OneDrive\Documents\SecureHome-main\SecureHome-main\main.py", line 128, in <module>
    gray = cv2.cvtColor(diff, cv2.COLOR_BGR2GRAY)
           ^^^^^^^^^^^^^^^^^^^^^^^^^^^^^^^^^^^^^^
cv2.error: OpenCV(4.7.0) D:\a\opencv-python\opencv-python\opencv\modules\imgproc\src\color.cpp:182: error: (-215:Assertion failed) !_src.empty() in function 'cv::cvtColor'

NoneType: None
Traceback (most recent call last):
  File "C:\Users\omtoi\OneDrive\Documents\SecureHome-main\SecureHome-main\main.py", line 171, in <module>
    img = detector.findPose(frame, draw=False)
          ^^^^^^^^^^^^^^^^^^^^^^^^^^^^^^^^^^^^
  File "C:\Users\omtoi\AppData\Local\Programs\Python\Python312\Lib\site-packages\cvzone\PoseModule.py", line 58, in findPose
    self.results = self.pose.process(imgRGB)
                   ^^^^^^^^^^^^^^^^^^^^^^^^^
  File "C:\Users\omtoi\AppData\Local\Programs\Python\Python312\Lib\site-packages\mediapipe\python\solutions\pose.py", line 185, in process
    results = super().process(input_data={'image': image})
              ^^^^^^^^^^^^^^^^^^^^^^^^^^^^^^^^^^^^^^^^^^^^
  File "C:\Users\omtoi\AppData\Local\Programs\Python\Python312\Lib\site-packages\mediapipe\python\solution_base.py", line 340, in process
    self._graph.wait_until_idle()
KeyboardInterrupt
NoneType: None
Traceback (most recent call last):
  File "C:\Users\omtoi\OneDrive\Documents\SecureHome-main\SecureHome-main\main.py", line 57, in <module>
    cap = cv2.VideoCapture(cam_n)
          ^^^^^^^^^^^^^^^^^^^^^^^
KeyboardInterrupt
NoneType: None
Traceback (most recent call last):
  File "C:\Users\omtoi\OneDrive\Documents\SecureHome-main\SecureHome-main\main.py", line 151, in <module>
    face_locations, face_names = fr.detect_known_faces(frame)
                                 ^^^^^^^^^^^^^^^^^^^^^^^^^^^^
  File "C:\Users\omtoi\OneDrive\Documents\SecureHome-main\SecureHome-main\dependencies\Facerec.py", line 52, in detect_known_faces
    face_encodings = face_recognition.face_encodings(rgb_small_frame, face_locations)
                     ^^^^^^^^^^^^^^^^^^^^^^^^^^^^^^^^^^^^^^^^^^^^^^^^^^^^^^^^^^^^^^^^
  File "C:\Users\omtoi\AppData\Local\Programs\Python\Python312\Lib\site-packages\face_recognition\api.py", line 213, in face_encodings
    return [np.array(face_encoder.compute_face_descriptor(face_image, raw_landmark_set, num_jitters)) for raw_landmark_set in raw_landmarks]
                     ^^^^^^^^^^^^^^^^^^^^^^^^^^^^^^^^^^^^^^^^^^^^^^^^^^^^^^^^^^^^^^^^^^^^^^^^^^^^^^^
KeyboardInterrupt
NoneType: None
Traceback (most recent call last):
  File "c:\Users\omtoi\OneDrive\Documents\SecureHome-main\SecureHome-main\main.py", line 128, in <module>
    diff = cv2.absdiff(frame, frame2)
           ^^^^^^^^^^^^^^^^^^^^^^^^^^
cv2.error: OpenCV(4.7.0) D:\a\opencv-python\opencv-python\opencv\modules\core\src\arithm.cpp:650: error: (-209:Sizes of input arguments do not match) The operation is neither 'array op array' (where arrays have the same size and the same number of channels), nor 'array op scalar', nor 'scalar op array' in function 'cv::arithm_op'

NoneType: None
Traceback (most recent call last):
  File "c:\Users\omtoi\OneDrive\Documents\SecureHome-main\SecureHome-main\main.py", line 58, in <module>
    cap.set(3, 1280)
KeyboardInterrupt
NoneType: None
Traceback (most recent call last):
  File "c:\Users\omtoi\OneDrive\Documents\SecureHome-main\SecureHome-main\main.py", line 129, in <module>
    gray = cv2.cvtColor(diff, cv2.COLOR_BGR2GRAY)
           ^^^^^^^^^^^^^^^^^^^^^^^^^^^^^^^^^^^^^^
cv2.error: OpenCV(4.7.0) D:\a\opencv-python\opencv-python\opencv\modules\imgproc\src\color.cpp:182: error: (-215:Assertion failed) !_src.empty() in function 'cv::cvtColor'

NoneType: None
Traceback (most recent call last):
  File "c:\Users\omtoi\OneDrive\Documents\SecureHome-main\SecureHome-main\main.py", line 129, in <module>
    gray = cv2.cvtColor(diff, cv2.COLOR_BGR2GRAY)
           ^^^^^^^^^^^^^^^^^^^^^^^^^^^^^^^^^^^^^^
cv2.error: OpenCV(4.7.0) D:\a\opencv-python\opencv-python\opencv\modules\imgproc\src\color.cpp:182: error: (-215:Assertion failed) !_src.empty() in function 'cv::cvtColor'

NoneType: None
Traceback (most recent call last):
  File "C:\Users\omtoi\AppData\Local\Programs\Python\Python312\Lib\multiprocessing\process.py", line 314, in _bootstrap
    self.run()
  File "C:\Users\omtoi\AppData\Local\Programs\Python\Python312\Lib\multiprocessing\process.py", line 108, in run
    self._target(*self._args, **self._kwargs)
  File "c:\Users\omtoi\OneDrive\Documents\SecureHome-main\SecureHome-main\main.py", line 48, in speak
    print(text)
  File "C:\Users\omtoi\AppData\Local\Programs\Python\Python312\Lib\site-packages\colorama\ansitowin32.py", line 41, in write
    self.__convertor.write(text)
  File "C:\Users\omtoi\AppData\Local\Programs\Python\Python312\Lib\site-packages\colorama\ansitowin32.py", line 162, in write
    self.write_and_convert(text)
  File "C:\Users\omtoi\AppData\Local\Programs\Python\Python312\Lib\site-packages\colorama\ansitowin32.py", line 190, in write_and_convert
    self.write_plain_text(text, cursor, len(text))
  File "C:\Users\omtoi\AppData\Local\Programs\Python\Python312\Lib\site-packages\colorama\ansitowin32.py", line 196, in write_plain_text
    self.wrapped.flush()
OSError: [Errno 22] Invalid argument

During handling of the above exception, another exception occurred:

Traceback (most recent call last):
  File "C:\Users\omtoi\AppData\Local\Programs\Python\Python312\Lib\multiprocessing\process.py", line 329, in _bootstrap
    sys.stderr.write('Process %s:\n' % self.name)
  File "C:\Users\omtoi\AppData\Local\Programs\Python\Python312\Lib\site-packages\colorama\ansitowin32.py", line 41, in write
    self.__convertor.write(text)
  File "C:\Users\omtoi\AppData\Local\Programs\Python\Python312\Lib\site-packages\colorama\ansitowin32.py", line 162, in write
    self.write_and_convert(text)
  File "C:\Users\omtoi\AppData\Local\Programs\Python\Python312\Lib\site-packages\colorama\ansitowin32.py", line 190, in write_and_convert
    self.write_plain_text(text, cursor, len(text))
  File "C:\Users\omtoi\AppData\Local\Programs\Python\Python312\Lib\site-packages\colorama\ansitowin32.py", line 195, in write_plain_text
    self.wrapped.write(text[start:end])
OSError: [Errno 22] Invalid argument

During handling of the above exception, another exception occurred:

Traceback (most recent call last):
  File "<string>", line 1, in <module>
  File "C:\Users\omtoi\AppData\Local\Programs\Python\Python312\Lib\multiprocessing\spawn.py", line 122, in spawn_main
    exitcode = _main(fd, parent_sentinel)
               ^^^^^^^^^^^^^^^^^^^^^^^^^^
  File "C:\Users\omtoi\AppData\Local\Programs\Python\Python312\Lib\multiprocessing\spawn.py", line 135, in _main
    return self._bootstrap(parent_sentinel)
           ^^^^^^^^^^^^^^^^^^^^^^^^^^^^^^^^
  File "C:\Users\omtoi\AppData\Local\Programs\Python\Python312\Lib\multiprocessing\process.py", line 334, in _bootstrap
    util._flush_std_streams()
  File "C:\Users\omtoi\AppData\Local\Programs\Python\Python312\Lib\multiprocessing\util.py", line 435, in _flush_std_streams
    sys.stdout.flush()
OSError: [Errno 22] Invalid argument
NoneType: None
deasdasdaasdTraceback (most recent call last):
  File "c:\Users\omtoi\OneDrive\Documents\SecureHome-main\SecureHome-main\main.py", line 129, in <module>
    gray = cv2.cvtColor(diff, cv2.COLOR_BGR2GRAY)
           ^^^^^^^^^^^^^^^^^^^^^^^^^^^^^^^^^^^^^^
cv2.error: OpenCV(4.7.0) D:\a\opencv-python\opencv-python\opencv\modules\imgproc\src\color.cpp:182: error: (-215:Assertion failed) !_src.empty() in function 'cv::cvtColor'

NoneType: None
ddasdsadTraceback (most recent call last):
  File "c:\Users\omtoi\OneDrive\Documents\SecureHome-main\SecureHome-main\main.py", line 111, in <module>
    with pyvirtualcam.Camera(frame_width, frame_height, fps, fmt=PixelFormat.BGR) as cam:
         ^^^^^^^^^^^^^^^^^^^^^^^^^^^^^^^^^^^^^^^^^^^^^^^^^^^^^^^^^^^^^^^^^^^^^^^^
  File "C:\Users\omtoi\AppData\Local\Programs\Python\Python312\Lib\site-packages\pyvirtualcam\camera.py", line 219, in __init__
    raise RuntimeError('\n'.join(errors))
RuntimeError: 'obs' backend: virtual camera output could not be started
'unitycapture' backend: No camera registered. Did you install any camera?
NoneType: None
Traceback (most recent call last):
  File "c:\Users\omtoi\OneDrive\Documents\SecureHome-main\SecureHome-main\main.py", line 152, in <module>
    face_locations, face_names = fr.detect_known_faces(frame)
                                 ^^^^^^^^^^^^^^^^^^^^^^^^^^^^
  File "c:\Users\omtoi\OneDrive\Documents\SecureHome-main\SecureHome-main\dependencies\Facerec.py", line 52, in detect_known_faces
    face_encodings = face_recognition.face_encodings(rgb_small_frame, face_locations)
                     ^^^^^^^^^^^^^^^^^^^^^^^^^^^^^^^^^^^^^^^^^^^^^^^^^^^^^^^^^^^^^^^^
  File "C:\Users\omtoi\AppData\Local\Programs\Python\Python312\Lib\site-packages\face_recognition\api.py", line 213, in face_encodings
    return [np.array(face_encoder.compute_face_descriptor(face_image, raw_landmark_set, num_jitters)) for raw_landmark_set in raw_landmarks]
                     ^^^^^^^^^^^^^^^^^^^^^^^^^^^^^^^^^^^^^^^^^^^^^^^^^^^^^^^^^^^^^^^^^^^^^^^^^^^^^^^
KeyboardInterrupt
NoneType: None
Traceback (most recent call last):
  File "c:\Users\omtoi\OneDrive\Documents\SecureHome-main\SecureHome-main\main.py", line 152, in <module>
    face_locations, face_names = fr.detect_known_faces(frame)
                                 ^^^^^^^^^^^^^^^^^^^^^^^^^^^^
  File "c:\Users\omtoi\OneDrive\Documents\SecureHome-main\SecureHome-main\dependencies\Facerec.py", line 52, in detect_known_faces
    face_encodings = face_recognition.face_encodings(rgb_small_frame, face_locations)
                     ^^^^^^^^^^^^^^^^^^^^^^^^^^^^^^^^^^^^^^^^^^^^^^^^^^^^^^^^^^^^^^^^
  File "C:\Users\omtoi\AppData\Local\Programs\Python\Python312\Lib\site-packages\face_recognition\api.py", line 213, in face_encodings
    return [np.array(face_encoder.compute_face_descriptor(face_image, raw_landmark_set, num_jitters)) for raw_landmark_set in raw_landmarks]
                     ^^^^^^^^^^^^^^^^^^^^^^^^^^^^^^^^^^^^^^^^^^^^^^^^^^^^^^^^^^^^^^^^^^^^^^^^^^^^^^^
KeyboardInterrupt
NoneType: None
Traceback (most recent call last):
  File "c:\Users\omtoi\OneDrive\Documents\SecureHome-main\SecureHome-main\main.py", line 111, in <module>
    with pyvirtualcam.Camera(frame_width, frame_height, fps, fmt=PixelFormat.BGR) as cam:
         ^^^^^^^^^^^^^^^^^^^^^^^^^^^^^^^^^^^^^^^^^^^^^^^^^^^^^^^^^^^^^^^^^^^^^^^^
  File "C:\Users\omtoi\AppData\Local\Programs\Python\Python312\Lib\site-packages\pyvirtualcam\camera.py", line 219, in __init__
    raise RuntimeError('\n'.join(errors))
RuntimeError: 'obs' backend: virtual camera output could not be started
'unitycapture' backend: No camera registered. Did you install any camera?
NoneType: None
Traceback (most recent call last):
  File "c:\Users\omtoi\OneDrive\Documents\SecureHome-main\SecureHome-main\main.py", line 111, in <module>
    with pyvirtualcam.Camera(frame_width, frame_height, fps, fmt=PixelFormat.BGR) as cam:
         ^^^^^^^^^^^^^^^^^^^^^^^^^^^^^^^^^^^^^^^^^^^^^^^^^^^^^^^^^^^^^^^^^^^^^^^^
  File "C:\Users\omtoi\AppData\Local\Programs\Python\Python312\Lib\site-packages\pyvirtualcam\camera.py", line 219, in __init__
    raise RuntimeError('\n'.join(errors))
RuntimeError: 'obs' backend: virtual camera output could not be started
'unitycapture' backend: No camera registered. Did you install any camera?
NoneType: None
Traceback (most recent call last):
  File "c:\Users\omtoi101\Downloads\SecureHome-main\main.py", line 142, in <module>
    _, frame2 = cap.read()
                ^^^^^^^^^^
KeyboardInterrupt
NoneType: None
Traceback (most recent call last):
  File "c:\Users\omtoi101\Downloads\SecureHome-main\main.py", line 129, in <module>
    gray = cv2.cvtColor(diff, cv2.COLOR_BGR2GRAY)
           ^^^^^^^^^^^^^^^^^^^^^^^^^^^^^^^^^^^^^^
cv2.error: OpenCV(4.11.0) D:\a\opencv-python\opencv-python\opencv\modules\imgproc\src\color.cpp:199: error: (-215:Assertion failed) !_src.empty() in function 'cv::cvtColor'

NoneType: None
Traceback (most recent call last):
  File "C:\Users\omtoi101\Downloads\SecureHome-main\main.py", line 129, in <module>
    gray = cv2.cvtColor(diff, cv2.COLOR_BGR2GRAY)
           ^^^^^^^^^^^^^^^^^^^^^^^^^^^^^^^^^^^^^^
cv2.error: OpenCV(4.11.0) D:\a\opencv-python\opencv-python\opencv\modules\imgproc\src\color.cpp:199: error: (-215:Assertion failed) !_src.empty() in function 'cv::cvtColor'

NoneType: None
Traceback (most recent call last):
  File "c:\Users\omtoi101\Downloads\SecureHome-main\main.py", line 152, in <module>
    face_locations, face_names = fr.detect_known_faces(frame)
                                 ^^^^^^^^^^^^^^^^^^^^^^^^^^^^
  File "c:\Users\omtoi101\Downloads\SecureHome-main\dependencies\Facerec.py", line 51, in detect_known_faces
    face_locations = face_recognition.face_locations(rgb_small_frame)
                     ^^^^^^^^^^^^^^^^^^^^^^^^^^^^^^^^^^^^^^^^^^^^^^^^
  File "C:\Users\omtoi101\AppData\Roaming\Python\Python312\site-packages\face_recognition\api.py", line 121, in face_locations
    return [_trim_css_to_bounds(_rect_to_css(face), img.shape) for face in _raw_face_locations(img, number_of_times_to_upsample, model)]
                                                                           ^^^^^^^^^^^^^^^^^^^^^^^^^^^^^^^^^^^^^^^^^^^^^^^^^^^^^^^^^^^^
  File "C:\Users\omtoi101\AppData\Roaming\Python\Python312\site-packages\face_recognition\api.py", line 105, in _raw_face_locations
    return face_detector(img, number_of_times_to_upsample)
           ^^^^^^^^^^^^^^^^^^^^^^^^^^^^^^^^^^^^^^^^^^^^^^^
KeyboardInterrupt
NoneType: None
Traceback (most recent call last):
  File "c:\Users\omtoi101\Downloads\SecureHome-main\main.py", line 172, in <module>
    img = detector.findPose(frame, draw=False)
          ^^^^^^^^^^^^^^^^^^^^^^^^^^^^^^^^^^^^
  File "C:\Users\omtoi101\AppData\Roaming\Python\Python312\site-packages\cvzone\PoseModule.py", line 58, in findPose
    self.results = self.pose.process(imgRGB)
                   ^^^^^^^^^^^^^^^^^^^^^^^^^
  File "C:\Users\omtoi101\AppData\Roaming\Python\Python312\site-packages\mediapipe\python\solutions\pose.py", line 185, in process
    results = super().process(input_data={'image': image})
              ^^^^^^^^^^^^^^^^^^^^^^^^^^^^^^^^^^^^^^^^^^^^
  File "C:\Users\omtoi101\AppData\Roaming\Python\Python312\site-packages\mediapipe\python\solution_base.py", line 340, in process
    self._graph.wait_until_idle()
KeyboardInterrupt
NoneType: None
Traceback (most recent call last):
  File "c:\Users\omtoi101\Downloads\SecureHome-main\main.py", line 129, in <module>
    gray = cv2.cvtColor(diff, cv2.COLOR_BGR2GRAY)
           ^^^^^^^^^^^^^^^^^^^^^^^^^^^^^^^^^^^^^^
cv2.error: OpenCV(4.11.0) D:\a\opencv-python\opencv-python\opencv\modules\imgproc\src\color.cpp:199: error: (-215:Assertion failed) !_src.empty() in function 'cv::cvtColor'

NoneType: None
Traceback (most recent call last):
  File "c:\Users\omtoi101\Downloads\SecureHome-main\main.py", line 129, in <module>
    blur = cv2.GaussianBlur(gray, (5,5), 0)
                            ^^^^
NameError: name 'gray' is not defined
NoneType: None
Traceback (most recent call last):
  File "c:\Users\omtoi101\Downloads\SecureHome-main\main.py", line 129, in <module>
    blur = cv2.GaussianBlur(gray, (5,5), 0)
                            ^^^^
NameError: name 'gray' is not defined
NoneType: None
Traceback (most recent call last):
  File "c:\Users\omtoi101\Downloads\SecureHome-main\main.py", line 151, in <module>
    face_locations, face_names = fr.detect_known_faces(frame)
                                 ^^^^^^^^^^^^^^^^^^^^^^^^^^^^
  File "c:\Users\omtoi101\Downloads\SecureHome-main\dependencies\Facerec.py", line 51, in detect_known_faces
    face_locations = face_recognition.face_locations(rgb_small_frame)
                     ^^^^^^^^^^^^^^^^^^^^^^^^^^^^^^^^^^^^^^^^^^^^^^^^
  File "C:\Users\omtoi101\AppData\Roaming\Python\Python312\site-packages\face_recognition\api.py", line 121, in face_locations
    return [_trim_css_to_bounds(_rect_to_css(face), img.shape) for face in _raw_face_locations(img, number_of_times_to_upsample, model)]
                                                                           ^^^^^^^^^^^^^^^^^^^^^^^^^^^^^^^^^^^^^^^^^^^^^^^^^^^^^^^^^^^^
  File "C:\Users\omtoi101\AppData\Roaming\Python\Python312\site-packages\face_recognition\api.py", line 105, in _raw_face_locations
    return face_detector(img, number_of_times_to_upsample)
           ^^^^^^^^^^^^^^^^^^^^^^^^^^^^^^^^^^^^^^^^^^^^^^^
KeyboardInterrupt
NoneType: None
Traceback (most recent call last):
  File "c:\Users\omtoi101\Downloads\SecureHome-main\main.py", line 141, in <module>
    _, frame2 = cap.read()
                ^^^^^^^^^^
KeyboardInterrupt
NoneType: None
